<?xml version="1.0" ?>
<!-- =================================================================================== -->
<!-- |    This document was autogenerated by xacro from hand.xacro                     | -->
<!-- |    EDITING THIS FILE BY HAND IS NOT RECOMMENDED                                 | -->
<!-- =================================================================================== -->
<robot name="hand_model" xmlns:xacro="http://www.ros.org/wiki/xacro">
  <link name="base_link">
    <visual>
      <origin rpy="0.5 0 0" xyz="0 0 0"/>
      <geometry>
        <mesh filename="package://urdf_display/meshes/base_link.STL"/>
      </geometry>
      <material name="">
        <color rgba="0.1 0.1 0.1 1"/>
      </material>
    </visual>
    <collision>
      <origin rpy="0.5 0 0" xyz="0 0 0"/>
      <geometry>
        <mesh filename="package://urdf_display/meshes/base_link.STL"/>
      </geometry>
    </collision>
  </link>

  <!-- <a> This is strange: Links for Finger 1 but true! </a>-->
  <link name="finger_1_1">
    <visual>
      <geometry>
        <mesh filename="package://urdf_display/meshes/swivel_1.STL"/>
      </geometry>
      <material name="">
        <color rgba="0.1 0.1 0.1 1"/>
      </material>
    </visual>
    <collision>
      <geometry>
        <mesh filename="package://urdf_display/meshes/swivel_1.STL"/>
      </geometry>
    </collision>
  </link>


  <joint name="base_to_finger_1_1" type="revolute">
    <parent link="base_link"/>
    <child link="finger_1_1"/>
    <limit effort="1000.0" lower="-2.0" upper="1.57" velocity="0.5"/>
    <axis xyz="0 0 -1"/>
    <origin rpy="0.5 0 0" xyz="0.0503973683071414 -0.026 0.063"/>
  </joint>

  <!-- This block connects the head_swivel joint to an actuator (motor), which informs both
  simulation and visualization of the robot -->
  <!-- <transmission name="finger1_1_trans" type="SimpleTransmission">
    <type>transmission_interface/SimpleTransmission</type>
    <actuator name="$finger11_motor">
      <mechanicalReduction>1</mechanicalReduction>
    </actuator>
    <joint name="base_to_finger_1_1">
      <hardwareInterface>hardware_interface/PositionJointInterface</hardwareInterface>
    </joint>
  </transmission>
  <transmission name="finger1_2_trans" type="SimpleTransmission">
    <type>transmission_interface/SimpleTransmission</type>
    <actuator name="$finger12_motor">
      <mechanicalReduction>1</mechanicalReduction>
    </actuator>
    <joint name="finger_1_1_to_finger_1_2">
      <hardwareInterface>hardware_interface/PositionJointInterface</hardwareInterface>
    </joint>
  </transmission>
  <transmission name="finger1_3_trans" type="SimpleTransmission">
    <type>transmission_interface/SimpleTransmission</type>
    <actuator name="$finger13_motor">
      <mechanicalReduction>1</mechanicalReduction>
    </actuator>
    <joint name="finger_1_2_to_finger_1_3">
      <hardwareInterface>hardware_interface/PositionJointInterface</hardwareInterface>
    </joint>
  </transmission>
  <transmission name="finger2_1_trans" type="SimpleTransmission">
    <type>transmission_interface/SimpleTransmission</type>
    <actuator name="$finger21_motor">
      <mechanicalReduction>1</mechanicalReduction>
    </actuator>
    <joint name="base_to_finger_2_1">
      <hardwareInterface>hardware_interface/PositionJointInterface</hardwareInterface>
    </joint>
  </transmission>
  <transmission name="finger2_2_trans" type="SimpleTransmission">
    <type>transmission_interface/SimpleTransmission</type>
    <actuator name="$finger22_motor">
      <mechanicalReduction>1</mechanicalReduction>
    </actuator>
    <joint name="finger_2_1_to_finger_2_2">
      <hardwareInterface>hardware_interface/PositionJointInterface</hardwareInterface>
    </joint>
  </transmission>
  <transmission name="finger2_3_trans" type="SimpleTransmission">
    <type>transmission_interface/SimpleTransmission</type>
    <actuator name="$finger23_motor">
      <mechanicalReduction>1</mechanicalReduction>
    </actuator>
    <joint name="finger_2_2_to_finger_2_3">
      <hardwareInterface>hardware_interface/PositionJointInterface</hardwareInterface>
    </joint>
  </transmission>
  <transmission name="finger3_1_trans" type="SimpleTransmission">
    <type>transmission_interface/SimpleTransmission</type>
    <actuator name="$finger31_motor">
      <mechanicalReduction>1</mechanicalReduction>
    </actuator>
    <joint name="base_to_finger_3_1">
      <hardwareInterface>hardware_interface/PositionJointInterface</hardwareInterface>
    </joint>
  </transmission>
  <transmission name="finger2_3_trans" type="SimpleTransmission">
    <type>transmission_interface/SimpleTransmission</type>
    <actuator name="$finger32_motor">
      <mechanicalReduction>1</mechanicalReduction>
    </actuator>
    <joint name="finger_3_1_to_finger_3_2">
      <hardwareInterface>hardware_interface/PositionJointInterface</hardwareInterface>
    </joint>
  </transmission>
  <transmission name="finger3_3_trans" type="SimpleTransmission">
    <type>transmission_interface/SimpleTransmission</type>
    <actuator name="$finger33_motor">
      <mechanicalReduction>1</mechanicalReduction>
    </actuator>
    <joint name="finger_3_2_to_finger_3_3">
      <hardwareInterface>hardware_interface/PositionJointInterface</hardwareInterface>
    </joint>
  </transmission>
  <gazebo>
    <plugin filename="libgazebo_ros_control.so" name="gazebo_ros_control">
      <robotNamespace>/hand</robotNamespace>
    </plugin>
  </gazebo> -->
</robot>
